Workbook

Sheet Resultados 
A1: B4 · Diez casos laborales
A3: Caso | B3: Concepto | C3: Resultado USD | D3: Días vacaciones | E3: Base del resultado | F3: Revisión | G3: Observación
A4: C01 | B4: Décimo tercero completo | C4: ='Calculos y fuentes'!G8 -> 600 | E4: 12 meses de USD 600 | F4: Revisado por contador | G4: Período 01-dic-2025 a 30-nov-2026.
A5: C02 | B5: Décimo tercero proporcional | C5: ='Calculos y fuentes'!G9 -> 250 | E5: 6 meses de USD 500 | F5: Revisado por contador | G5: Ingreso 01-jun-2026; corte 30-nov-2026.
A6: C03 | B6: Décimo tercero variable | C6: ='Calculos y fuentes'!G10 -> 737.5 | E6: 9 meses de USD 700 y 3 de USD 850 | F6: Revisado por contador | G6: Mismo período completo de C01.
A7: C04 | B7: Décimo cuarto Sierra | C7: ='Calculos y fuentes'!G11 -> 482 | E7: Período completo, SBU 2026 | F7: Revisado por contador | G7: 01-ago-2025 a 31-jul-2026.
A8: C05 | B8: Décimo cuarto Costa | C8: ='Calculos y fuentes'!G12 -> 241 | E8: 6 meses, SBU 2026 | F8: Revisado por contador | G8: Ingreso 01-sep-2025; corte 28-feb-2026.
A9: C06 | B9: Vacaciones un año | C9: ='Calculos y fuentes'!G13 -> 300 | D9: ='Calculos y fuentes'!D13 -> 15 | E9: USD 600; 15 días | F9: Revisado por contador | G9: Ingreso 01-oct-2025; consulta 01-oct-2026.
A10: C07 | B10: Vacaciones con antigüedad | C10: ='Calculos y fuentes'!G14 -> 510 | D10: ='Calculos y fuentes'!D14 -> 17 | E10: USD 900; 7 años cumplidos | F10: Revisado por contador | G10: 17 días: 15 base + 2 adicionales.
A11: C08 | B11: Horas suplementarias y extraordinarias | C11: =SUM('Calculos y fuentes'!G15:G16) -> 76.67 | E11: USD 800; 10 h al 50% y 4 h al 100% | F11: Revisado por contador | G11: Total de rubros redondeados; valor de hora sin redondeo intermedio.
A12: C09 | B12: Renuncia con desahucio | C12: =SUM('Calculos y fuentes'!G17:G20) -> 1130.33 | E12: USD 700; 01-jun-2024 a 30-sep-2026 | F12: Revisado por contador | G12: Desahucio por 2 años completos. Criterio conservado.
A13: C10 | B13: Despido intempestivo | C13: =SUM('Calculos y fuentes'!G21:G25) -> 9331.84 | E13: USD 1.000; 01-ago-2020 a 31-ago-2026 | F13: Revisado por contador | G13: Se conserva el supuesto sin vacaciones adicionales y el resultado original; no generalizar a otros casos.
A17: Condiciones de los casos: en C09 y C10, el sueldo del último mes y los beneficios de períodos anteriores ya fueron pagados. Se calculan únicamente los valores pendientes del período actual.
A18: Criterio de tiempo: se utilizan meses de 30 días y años de 360 días. En C06 y C07, la fecha de consulta coincide con el aniversario laboral, por lo que no se agrega un día.
A19: Vacaciones de C10: el resultado presentado considera únicamente las vacaciones proporcionales base, sin días adicionales por antigüedad.
A20: Revisión: Los casos fueron revisados uno a uno por un contador. El desarrollo se encuentra al final de Calculos y fuentes.

Sheet Calculos y fuentes
A1: Cálculos reproducibles y fuentes
A3: Parámetro | B3: Valor | C3: Unidad | D3: Fuente
A4: SBU 2026 | B4: 482 | C4: USD | D4: S2
A5: Mes laboral | B5: 30 | C5: días | D5: S3, disposición general quinta
A6: Año laboral | B6: 360 | C6: días | D6: S3, disposición general quinta
A7: Caso | B7: Rubro | C7: Base USD | D7: Cantidad | E7: Unidad / divisor | F7: Sin redondear USD | G7: Final USD | H7: Procedimiento / fuente
A8: C01 | B8: Décimo tercero | C8: 600 | D8: 12 | E8: 12 | F8: =C8*D8/E8 -> 600 | G8: =ROUND(F8,2) -> 600 | H8: S1 art. 111; suma de remuneraciones / 12.
A9: C02 | B9: Décimo tercero | C9: 500 | D9: 6 | E9: 12 | F9: =C9*D9/E9 -> 250 | G9: =ROUND(F9,2) -> 250 | H9: S1 art. 111; junio a noviembre: 6 meses. | J9: C03: segundo tramo
A10: C03 | B10: Décimo tercero variable | C10: 700 | D10: 9 | E10: 12 | F10: =(C10*D10+J10*K10)/E10 -> 737.5 | G10: =ROUND(F10,2) -> 737.5 | H10: S1 art. 111; (700 × 9 + 850 × 3) / 12. | J10: 850 | K10: 3
A11: C04 | B11: Décimo cuarto Sierra | C11: =$B$4 -> 482 | D11: 12 | E11: 12 | F11: =C11*D11/E11 -> 482 | G11: =ROUND(F11,2) -> 482 | H11: S1 art. 113; S2; S3 arts. 9 y 10.
A12: C05 | B12: Décimo cuarto Costa | C12: =$B$4 -> 482 | D12: 6 | E12: 12 | F12: =C12*D12/E12 -> 241 | G12: =ROUND(F12,2) -> 241 | H12: S1 art. 113; S2: SBU de pago 2026; septiembre a febrero.
A13: C06 | B13: Vacaciones base | C13: 600 | D13: 15 | E13: 30 | F13: =C13*D13/E13 -> 300 | G13: =ROUND(F13,2) -> 300 | H13: S1 arts. 69 y 71. Equivalente sueldo × 12 / 24, sin variables.
A14: C07 | B14: Vacaciones base y antigüedad | C14: 900 | D14: 17 | E14: 30 | F14: =C14*D14/E14 -> 510 | G14: =ROUND(F14,2) -> 510 | H14: S1 arts. 69–71. Base 450 + 2 × (900/30) = 510; revisar valoración adicional. | J14: Recargo
A15: C08 | B15: Horas suplementarias | C15: 800 | D15: 10 | E15: 240 | F15: =C15/E15*D15*(1+J15) -> 50 | G15: =ROUND(F15,2) -> 50 | H15: S1 art. 55; S5 art. 24. Recargo adicional al valor hora. | J15: 0.5
A16: C08 | B16: Horas extraordinarias | C16: 800 | D16: 4 | E16: 240 | F16: =C16/E16*D16*(1+J16) -> 26.666667 | G16: =ROUND(F16,2) -> 26.67 | H16: S1 art. 55; S5 art. 24. Recargo adicional al valor hora. | J16: 1
A17: C09 | B17: Bonificación por desahucio | C17: 700 | D17: 2 | E17: 0.25 | F17: =C17*D17*E17 -> 350 | G17: =ROUND(F17,2) -> 350 | H17: S1 art. 185: criterio de años completos; fracción no redondeada como despido. Revisar.
A18: C09 | B18: Décimo tercero proporcional | C18: 700 | D18: 10 | E18: 12 | F18: =C18*D18/E18 -> 583.33333 | G18: =ROUND(F18,2) -> 583.33 | H18: S1 art. 111; dic-2025 a sep-2026: 10 meses.
A19: C09 | B19: Décimo cuarto Sierra | C19: =$B$4 -> 482 | D19: 2 | E19: 12 | F19: =C19*D19/E19 -> 80.333333 | G19: =ROUND(F19,2) -> 80.33 | H19: S1 art. 113; S2; agosto y septiembre 2026.
A20: C09 | B20: Vacaciones proporcionales | C20: 700 | D20: 120 | E20: 720 | F20: =C20*D20/E20 -> 116.66667 | G20: =ROUND(F20,2) -> 116.67 | H20: S1 art. 71; junio a septiembre: 4 × 30 días; sueldo × días / 720.
A21: C10 | B21: Indemnización por despido | C21: 1000 | D21: 7 | E21: 25 | F21: =C21*MIN(D21,E21) -> 7000 | G21: =ROUND(F21,2) -> 7000 | H21: S1 art. 188: 6 años + fracción se cuentan como 7; tope 25.
A22: C10 | B22: Bonificación por desahucio | C22: 1000 | D22: 6 | E22: 0.25 | F22: =C22*D22*E22 -> 1500 | G22: =ROUND(F22,2) -> 1500 | H22: S1 arts. 185 y 188; 6 años completos, criterio a contrastar.
A23: C10 | B23: Décimo tercero proporcional | C23: 1000 | D23: 9 | E23: 12 | F23: =C23*D23/E23 -> 750 | G23: =ROUND(F23,2) -> 750 | H23: S1 art. 111; diciembre 2025 a agosto 2026: 9 meses.
A24: C10 | B24: Décimo cuarto Sierra | C24: =$B$4 -> 482 | D24: 1 | E24: 12 | F24: =C24*D24/E24 -> 40.166667 | G24: =ROUND(F24,2) -> 40.17 | H24: S1 art. 113; S2; agosto 2026: un mes.
A25: C10 | B25: Vacaciones proporcionales sin adicionales | C25: 1000 | D25: 30 | E25: 720 | F25: =C25*D25/E25 -> 41.666667 | G25: =ROUND(F25,2) -> 41.67 | H25: S1 art. 71; supuesto recibido: solo agosto, sin adicionales. Revisar contra art. 69.
A28: Sensibilidades para revisión — no incluidas en los totales principales
A29: Caso | B29: Alternativa | C29: Base USD | D29: Cantidad | E29: Divisor / tasa | F29: Sin redondear USD | G29: Final USD | H29: Motivo de revisión
A30: C09 | B30: Desahucio proporcional hipotético | C30: 700 | D30: 2.3333333 | E30: 0.25 | F30: =C30*D30*E30 -> 408.33333 | G30: =ROUND(F30,2) -> 408.33 | H30: Solo contraste: no afirmar que art. 185 exige proporcionalidad sin validación oficial.
A31: C10 | B31: Desahucio proporcional hipotético | C31: 1000 | D31: 6.0833333 | E31: 0.25 | F31: =C31*D31*E31 -> 1520.8333 | G31: =ROUND(F31,2) -> 1520.83 | H31: Solo contraste: no afirmar que art. 185 exige proporcionalidad sin validación oficial.
A32: C10 | B32: Vacaciones con 1 día anual adicional | C32: 1000 | D32: 30 | E32: 360 | F32: =C32/30*16*D32/E32 -> 44.444444 | G32: =ROUND(F32,2) -> 44.44 | H32: Ilustración: 16 días anuales con 6 años cumplidos; revisar derecho y tratamiento proporcional.
A34: C07: 7 años cumplidos al 01-mar-2026, 2 días adicionales. C09: 2 años y 4 meses. C10: 6 años y 1 mes. Meses expresados en base comercial de 30 días, según condiciones de los ejercicios.
A36: Fuentes consultadas el 19-oct-2026
A37: S1 | B37: Código del Trabajo — Arts. 55, 69–71, 95, 111, 113, 184–185 y 188
B38: https://portal.compraspublicas.gob.ec/sercop/wp-content/uploads/2026/01/CO%CC%81DIGO-DEL-TRABAJO.pdf
A40: S2 | B40: MDT-2025-195 — Artículo único: SBU 2026 = USD 482
B41: https://www.trabajo.gob.ec/wp-content/uploads/downloads/2026/01/ACUERDO-MINISTERIAL-MDT-2025-195.pdf
A43: S3 | B43: MDT-2023-140 — Arts. 9–10: períodos; disposición general quinta: base comercial
B44: https://www.trabajo.gob.ec/wp-content/uploads/downloads/2024/01/MDT-2023-140-AM-Obligaciones-empleador-y-procedimientos-de-inspeccion-14-11-23-signed.pdf
A46: S4 | B46: MDT-2025-053 — Reforma al MDT-2023-140; no modifica arts. 9 y 10
B47: https://www.trabajo.gob.ec/wp-content/uploads/2025/06/ACUERDO-MINISTERIAL-MDT-2025-053.pdf
A49: S5 | B49: Resolución INEC 021-DIREJ-DIJU-NI-2026 — Art. 24: referencia institucional de divisor 240 bajo Código del Trabajo
...
